# 목표
자바의 예외 처리에 대해 학습하세요
<br><br>
<hr>

## 1. 자바에서 예외 처리 방법 (try, catch, throw, throws, finally)
프로그램을 짤 때 우리가 예상한 플로우대로 가지 않는 경우가 필연적으로 존재할 수 밖에 없다.  
이를 처리하기 위해 예외가 존재한다.


예외에 대해 알아보자.
```java
public class ExceptionSample {
    public static void main(String[] args) {
        ExceptionSample sample = new ExceptionSample();
        sample.arrayOutOfBounds();
    }

    public void arrayOutOfBounds() {
        int[] intArray = new int[5];
        System.out.println(intArray[5]);
    }
}
```

위의 코드를 컴파일하면 어떻게 될까?

...

```java
Exception in thread "main" java.lang.ArrayIndexOutOfBoundsException: Index 5 out of bounds for length 5
	at com.company.week9.ExceptionSample.arrayOutOfBounds(ExceptionSample.java:12)
	at com.company.week9.ExceptionSample.main(ExceptionSample.java:7)
```

코드가 논리적으로 말은 안되지만 자바는 위의 코드도 정상적으로 컴파일 한 후에 실행한다.   
실행 후 예외를 확인할 수 있다.

예외가 날 때 수도 없는 Exception들이 연달아 적히는 것을 확인 할 수 있을 것이다.
첫 줄은 현재 발생한 예외를 알려 주는 것이고 그 다음줄부터는 call stack trace이다.

가장 윗줄은 예외가 발생한 클래스와 메소드 이름, 줄번호를 출력  
그 아래에는 그 메소드를 호출한 클래스와 메소드의 이름 및 줄번호 들이 줄줄이 출력된다.
<br><br><br>

### try, catch finally
```java
public void arrayOutOfBoundTryCatch() {
    try {
        int[] intArray = new int[5];
        System.out.println(intArray[5]);
    } catch (Exception e) {
    }
}
```

위의 코드를 아래 메소드로 실행하면 어떻게 될까?  
아까와 같이 예외는 뜨지 않지만 예외는 발생했다. try 문에서 예외가 발생하면 그 줄 이후의 try 코드들은 수행되지 않는다.
그리고 그 밖의 문장은 정상 실행된다.

```java
public class ExceptionVariable {
    public static void main(String[] args) {
        ExceptionVariable sample = new ExceptionVariable();
        sample.checkVariable();
    }
    public void checkVariable() {
        try {
            int[] inyArray = new int[5];
            System.out.println(inyArray[5]);
            
        } catch (Exception e) {
            System.out.println(inyArray.length);
        }
        System.out.println("This code must run");
    }
}
```

위의 코드는 실행될까?  
안된다. 배열의 선언을 블록 안에 했기 때문에 외부 스택의 데이터에 접근할 수 없다.

```java
public class ExceptionVariable {
    public static void main(String[] args) {
        ExceptionVariable sample = new ExceptionVariable();
        sample.checkVariable();
    }
    public void checkVariable() {
        int[] intArray = null;
        try {
            intArray = new int[5];
            System.out.println(inyArray[5]);
        } catch (Exception e) {
            System.out.println(intArray.length);
        }
        System.out.println("This code must run");
    }
}
```

이건 어떻게 될까요? 모르면 2주차 다시공부해라

이제 finally에 대해 알아보자.

```java
public class FinallySample {
    public static void main(String[] args) {
        FinallySample sample = new FinallySample();
        sample.finallySample();
    }

    public void finallySample() {
        int[] intArray = new int[5];
        try {
            System.out.println(intArray[5]);
        } catch (Exception e) {
            System.out.println(intArray.length);
        } finally {
            System.out.println("Here is finally");
        }
        System.out.println("This code must run");
    }
}
```

finally 는 무조건 실행되는 블록이다. Exception이 있으나 없으나 같다.

```java
public class MultiCatchSample {
    public static void main(String[] args) {
        MultiCatchSample sample = new MultiCatchSample();
        sample.multiCatch();
    }
    public void multiCatch() {
        int[] intArray = new int[5];
        try {
            System.out.println(intArray[5]);
        } catch (ArrayIndexOutOfBoundsException e) {
            System.err.println("ArrayIndexOutOfBoundException occurred");
        } catch (Exception e) {
            System.out.println(intArray.length);
        }
    }
}
```
위의 코드는 정상적인 try catch문을 이용한 에러 캐치다.

에러 순서를 바꿔서 아래와 같이 하면?
```java
public class MultiCatchSample {
    public static void main(String[] args) {
        MultiCatchSample sample = new MultiCatchSample();
        sample.multiCatch();
    }
    public void multiCatch() {
        int[] intArray = new int[5];
        try {
            System.out.println(intArray[5]);
        } catch (Exception e) {
            System.out.println(intArray.length);
        } catch (ArrayIndexOutOfBoundsException e) {
            System.err.println("ArrayIndexOutOfBoundException occurred");
        }
    }
}

/Users/hojin/Desktop/git_local/java_practice/src/com/company/week9/MultiCatchSample.java:14:11
java: exception java.lang.ArrayIndexOutOfBoundsException has already been caught
```
치우란다.  
Exception은 모든 객체의 부모 Object처럼 모든 Exception의 부모다. 물론 Exception도 Object의 자식이다.  
 위의 코드에서 Exception 아래의 코드는 실행될리 없는 Exception이다. 따라서 컴파일에서 걸려부린다.

- 정리
  - try 다음에 오는 catch 블록은 1개 이상이 가능하다.
  - 먼저 선언한 catch 블록의 예외 클래스가 다음 catch 블록의 부모에 속하면 자식은 실행될 수 없으므로 컴파일 되지 않는다.
  - 하나의 try 블록에서 예외가 발생하면 그 예외와 관련있는 catch 블록을 찾아서 실행한다.
  - 최후순위에는 Exception으로 잡아줘야 try-catch 블록을 사용하는 의미가 있어진다. catch 블록중 예외와 관련있는 블록이 없으면 해당 쓰레드가 끝나버린다.

### throw, throws
```java
public class ThrowSample {
    public static void main(String[] args) {
        ThrowSample sample = new ThrowSample();
        sample.throwException(13);
    }

    public void throwException(int number) {
        try {
            if (number > 12) {
                throw new Exception("Number is over than 12");
            }
            System.out.println("Number is " + number);
        } catch (Exception e) {
            e.printStackTrace();
        }
    }
}
```

1년 12달을 생각하고 13이 되면 예외를 던지는 코드다. 헌데 만약 catch문에 해당하는 Exception이 없다면 발생된 예외는 메소드 밖으로 던져져 메소드를 호출한 메소드가 책임져야 한다. 이 때 사용하는게 throws다.

```java
public class ThrowSample {
    public static void main(String[] args) {
        ThrowSample sample = new ThrowSample();
        sample.throwException(13);
    }

    public void throwsException(int number) throws Exception {
        if (number > 12) {
            throw new Exception("Number is over than 12");
        }
        System.out.println("Number is " + number);
    }
}
```
이제 main한테 폭탄이 던져졌다. 물론 이 상태에서 컴파일 하려 하면 안된다. 내부적으로 던져진 exception을 처리할 방법이 없으니께

여기서 처리할 방법은 두 가지가 있다.
아까 말했다. 사실 말했는지 기억은 안나지만 어쨋든 exception을 처리하지 않고 그대로 맞으면 해당 스레드가 종료된다. 성능상 좋지 않다. 내부에서 처리해주는게 낫다. 따라서 <br><br>
1. main에서도 try-catch로 묶는다.
```java
public static void main(String[] args) {
    ThrowSample sample = new ThrowSample();
    sample.throwException(13);
    try {
        sample.throwsException(13);
    } catch (Exception e) {
        e.printStackTrace();
    }
}
```

2. main에서마저 똥을 넘긴다
```java
public static void main(String[] args) throws Exception {
    ThrowSample sample = new ThrowSample();
    sample.throwException(13);
    sample.throwsException(13);
}
```
- 정리
  - 메소드를 선언할 때 throws라는 예약어를 적어 준 뒤 예외를 선언하면 해당 메소드에서 호출 메소드로 예외가 전달된다.
  - try에서 예외를 발생시킬 경우 throw라는 예약어를 적어준 뒤 예외 객체를 생성하거나 생성되어 있는 객체를 명시해준다. 이것을 catch에서 처리하지 않거나 throws에 포함되어있지 않으면 예외가 발생한다.


<br><br><hr>

## 2. 자바가 제공하는 예외 계층 구조
예외의 종류는 세가지라고 생각할 수 있다. 물론 error는 '예외'는 아니지만.

- checked exception
- errer
- runtime exception 혹은 unchecked exception

error와 unchecked exception을 제외한 모든 예외는 checked exception이다.

- error는 자바 프로그램 밖에서 발생한 예외를 말한다.  
하드웨어나 외부 소프트웨어의 문제로 자바 프로그램이 제대로 동작하지 못할 때가 여기에 속한다. 따라서, Error는 프로세스에 영향을 주고 Exception은 쓰레드에만 영향을 준다.

- runtime exception은 예외가 발생할 것을 미리 감지하지 못했을 때 발생한다.  
RuntimeException을 확장한 예외들로 NullPointerException도 여기에 속한다. 컴파일 시에는 발생하지 않지만 실행시에는 발생할 가능성이 있다. 컴파일시 체크하지 못하기 때문에 unchecked exception이라고도 이야기 한다.

<img width="526" alt="Exception" src="https://user-images.githubusercontent.com/67143721/192082917-fa2e0b93-aa05-48d7-93ca-734d31c159d4.png">

Exception을 바로 확장한 친구들이 checked exception이고 RuntimeException 밑의 확장된 클래스들이 런타임 예외들이다.

위의 사진을 보면 error와 Exception이 Throwable을 상속하고 있는 것을 알 수 있는데 Exception과 Error는 성격이 다르지만 동일한 이름의 메소드로 처리할 수 있게 하기 위해 만들어졌다.

Throwable에는 다음과 같은 생성자들이 존재한다.

- Throwable()  
- Throwable(String message)  
- Throwable(String message, Throwable cause)  
- Throwable(Throwable cause)  

메소드들은 10개가 넘는데 자주 사용하는건 아래 세개 정도고 Exception이 Overriding 하고있다.  
- getMessage()  
- toString()  
- printStackTrace()  

위의 세 가지 메서드에 대해 알아보면 

getMessage()  
예외 메시지를 String 형태로 제공 받고 예외가 출력되었을 때 어떤 예외가 발생했는지 확일할 때 유용한다.
주로 별도의 예외 메시지를 사용자에게 보여주려고 할 때 좋다.

toString()
예외 메시지를 String 형태로 제공 받는다. getMessage()보다 조금 더 자세하게 예외 클래스 이름도 제공한다.

printStackTrace()
첫 줄에는 예외 메시지를 출력하고 두 번째 줄부터는 예외가 발생하게 된 메소드들의 stack trace를 출력해준다.

```java
public class ThrowableSample {
    public static void main(String[] args) {
        ThrowableSample sample = new ThrowableSample();
        sample.throwable();
    }
    public void throwable() {
        int[] intArray = new int[5];
        try {
            intArray = null;
            System.out.println(intArray[5]);
        } catch (Throwable t) {
            System.out.println(t.getMessage());
        }
    }
}
```

NPE를 뱉도록 코딩해봤다. getMessage()의 결과는 다음과 같다.  <br>
`null`  <br><br>
위의 t.getMessage()를 t.toString()으로 바꾸면 에러 클래스를 반환해준다.  
`java.lang.NullPointerException`  <br><br>
이보다 자세한 메시지를 얻으려면 printStackTrace()를 사용하면 된다.  
```java
java.lang.NullPointerException
	at com.company.week9.ThrowableSample.throwable(ThrowableSample.java:12)
	at com.company.week9.ThrowableSample.main(ThrowableSample.java:6)
```
추가로 printStackTrace()는 자세한 메시지를 볼 수 있지만 운영에서 사용하면 리소스를 많이 필요로 하기 때문에 꼭 필요한 곳에서만 사용해야 한다.

<br><br><hr>

## 3. 커스텀한 예외 만드는 방법

위에서 봤듯 Throwable을 직접 상속받는 클래스는 Exception과 Error가 있다. Error 관련 클래스는 손 댈 필요가 없다. 하지만 Exception은 개발자가 임의로 추가해서 만들 수 있다.

```java
public class MyException extends Exception{
    public MyException() {
        super();
    }
    public MyException(String message) {
        super(message);
    }
}
```

```java
public class CustomException {
    public static void main(String[] args) {
        CustomException sample = new CustomException();
        try {
            sample.throwMyException(13);
        } catch (MyException mye) {
            mye.printStackTrace();
        }
    }
    public void throwMyException(int number) throws MyException {
        try {
            if(number > 12) {
                throw new MyException("Number is over than 12");
            }
        } catch (MyException e) {
            e.printStackTrace();
        }
    }
}
```
다음과 같이 Exception을 extends해서 CustomException을 만들고 사용하면 된다.

예외의 종류는 세 가지라고 이야기 했었다.
- checked exception
- errer
- runtime exception 혹은 unchecked exception

만약 직접 만든 예외가 항상 발생하지 않고 실행시에 발생할 확률이 높은 경우에는 런타임 예외로 만드는 것이 낫다.
extends Exception이 아닌 RuntimeException으로 만드는 것이다. 이렇게 하면 해당 예외를 던지는 메소드를 사용하더라도 try-catch로 묶지 않아도 컴파일시 예외가 발생하지 않는다.

하지만 해당 메소드를 call하는 메소드에서는 try-catch로 묶는 것이 권장된다.

<br><br><hr>

## 4 표준 예외와 사용자 정의 예외
이펙티브 자바 Item 72 에서는 표준 예외를 사용하는 것이 좋다고 말한다

많이 사용될 수 있는 예외들로 다음 친구들을 이야기한다.

| 예외        | 주요 쓰임  |
|---------------------------------|---|
| IllegalArgumentException        | 혀용하지 않는 값이 인수로 건네졌을 때   |
| IllegalStateException           | 객체가 메서드를 수행하기에 적절하지 않은 상태일 때 |
| NullPointerException            | null을 허용하지 않는 메서드에 null을 건넸을 때 |
| IndexOutOfBoundException        | 인덱스가 범위를 넘어섰을 때 |
| ConcurrentModificationException | 허용하지 않는 동시 수정이 발견됐을 때 |
| UnsupportedOperationException   | 호출한 메서드를 지원하지 않을 때 |

커스텀 예외 처리를 써야하는지에 대한 논의는 항상 있어왔는데 각각의 장단점을 알아보고 알아서 판단해야 할 것 같다.  
우테코 블로그에서 가져왔다.

표준 예외를 써야하는 이유  
1. 예외 메시지로도 충분히 의미를 전달할 수 있다.
물론 더 정확하게 에러가 발생한 이유로 에러 클래스를 만들어도 되겠지만 메시지만 예외상황에 맞게 재정의해준다면 충분히 의미를 파악할 수 있다.
2. 표준 예외를 사용하면 가독성이 높아진다.
3. 일일이 만들다보면 커스텀 예외가 많아지고 중복도 생길 수 있다.

커스텀 예외를 써야 하는 이유
1. 이름으로도 정보 전달이 가능하다.
2. 상세한 예외 정보를 제공할 수 있다.
```java
public class IllegalIndexSample {
    public static void main(String[] args) {
        List[] intArray = new ArrayList[5];
        int i = 0;
        try {
            for (i = 0; i < 6; i++) {
                System.out.println(intArray[i]);
            }
        } catch (IndexOutOfBoundsException e) {
            throw new IllegalIndexException(intArray, i);
        }
    }
}

public class IllegalIndexException extends IndexOutOfBoundsException{
    private static final String message = "범위를 벗어났습니다.";

    public IllegalIndexException(List[] target, int index) {
        super(message + " size: " + target.length + " index " + index);
    }
}
```
다음과 같이 구현했다고 했을 때 정확히 어느 부분에서 에러가 났는지 정확하게 알 수 있다.

3. 예외에 대한 응집도가 향상된다.  
클래스를 만드는 행위는 관련 정보를 해당 클래스에서 최대한 관리하겠다는 이야기로 예외를 던져야 하는 상황이 많아지고 전달하는 정보의 양이 많아질수록 코드가 더러워질 수 밖에 없다. 

4. 예외 발생 후 후처리가 용이하다.  
Spring에서는 ControllerAdvice를 통해 전역적인 예외처리가 가능하다.
모두 IllegalArgumentException을 반환한다면 내가 쓴 코드에서 난 에러인지 사용한 라이브러리에서 발생한 에러인지 혼동이 온다. 내가 만든 에러만 가져와서 공통적으로 처리하고 싶다면 커스텀 예외를 구현한 뒤 일관성있게 처리 로직을 정의할 수 있다.
```java
// in GlobalExceptionHandler.java
@RestControllerAdvice
public class GlobalExceptionHandler {
    @ExceptionHandler(RuntimeException.class)
    public ResponseEntity<ErrorResponse> handleUnExpectedException(final RuntimeException error) {
        // ...
    }

    @ExceptionHandler(ExpectedException.class)
    public ResponseEntity<ErrorResponse> handleExpectedException(final ExpectedException error) {
        // ...
    }
    // ...
}
```

5. 예외 생성 비용을 절감할 수 있다.
위에서 말한 stack trace는 상당한 비용이다. stack trace는 예외 발생 시 call stack을 저장하는데 이를 통해 예외 발생 위치를 파악할 수 있다. 하지만 수 많은 call stack이 전부 담기게 되므로 비효율적이다.

stack trace의 생성은 Throwable의 fillInStackTrace() 메소드를 통해 이뤄지는데 이를 Override해 필요한 정보만 넣어주면 stack trace의 비용을 아낄 수 있다.

<hr>
출처: https://tecoble.techcourse.co.kr/post/2020-08-17-custom-exception/  

자바의 신
